Watching for file changes with StatReloader
Error: That port is already in use.
Watching for file changes with StatReloader
Error: That port is already in use.
Watching for file changes with StatReloader
Error: That port is already in use.
Watching for file changes with StatReloader
Error: That port is already in use.
Watching for file changes with StatReloader
Error: That port is already in use.
Watching for file changes with StatReloader
Error: That port is already in use.
Watching for file changes with StatReloader
Error: That port is already in use.
Watching for file changes with StatReloader
Error: That port is already in use.
Watching for file changes with StatReloader
Error: That port is already in use.
Traceback (most recent call last):
  File "/home/ubuntu/crtd_new/manage.py", line 11, in main
    from django.core.management import execute_from_command_line
ModuleNotFoundError: No module named 'django'

The above exception was the direct cause of the following exception:

Traceback (most recent call last):
  File "/home/ubuntu/crtd_new/manage.py", line 22, in <module>
    main()
  File "/home/ubuntu/crtd_new/manage.py", line 13, in main
    raise ImportError(
ImportError: Couldn't import Django. Are you sure it's installed and available on your PYTHONPATH environment variable? Did you forget to activate a virtual environment?
Traceback (most recent call last):
  File "/home/ubuntu/crtd_new/manage.py", line 11, in main
    from django.core.management import execute_from_command_line
ModuleNotFoundError: No module named 'django'

The above exception was the direct cause of the following exception:

Traceback (most recent call last):
  File "/home/ubuntu/crtd_new/manage.py", line 22, in <module>
    main()
  File "/home/ubuntu/crtd_new/manage.py", line 13, in main
    raise ImportError(
ImportError: Couldn't import Django. Are you sure it's installed and available on your PYTHONPATH environment variable? Did you forget to activate a virtual environment?
Traceback (most recent call last):
  File "/home/ubuntu/crtd_new/manage.py", line 11, in main
    from django.core.management import execute_from_command_line
ModuleNotFoundError: No module named 'django'

The above exception was the direct cause of the following exception:

Traceback (most recent call last):
  File "/home/ubuntu/crtd_new/manage.py", line 22, in <module>
    main()
  File "/home/ubuntu/crtd_new/manage.py", line 13, in main
    raise ImportError(
ImportError: Couldn't import Django. Are you sure it's installed and available on your PYTHONPATH environment variable? Did you forget to activate a virtual environment?
